Start time: 22:13
dataset: redcaps1m
N: 1000000
dataset file: /mnt/data/mocheng/dataset/redcaps1m/image_embeddings.fvecs
query file: /mnt/data/mocheng/dataset/redcaps1m/query.fvecs
attr file: /mnt/data/mocheng/dataset/redcaps1m/label/sel_1_100000_real/attr_sel_1_100000_real.json
query range file: /mnt/data/mocheng/dataset/redcaps1m/label/sel_1_100000_real/qrangesel_6_1_100000_real.json
ground truth file: /mnt/data/mocheng/dataset/redcaps1m/label/sel_1_100000_real/sif_gt_sel_6_1_100000_real_100.json
K: 100
nprobe: 120
collection name: collection_redcaps1m_sel_1_100000_real_512
2025-07-18 13:13:16,474 [ERROR][_create_connection]: Failed to create new connection using: f3420cf593234b868494ac5e54760108 (milvus_client.py:923)
Traceback (most recent call last):
  File "utils/pymilvus_ivfpq.py", line 67, in <module>
    client = MilvusClient(
  File "/home/mocheng/anaconda3/envs/py38/lib/python3.8/site-packages/pymilvus/milvus_client/milvus_client.py", line 67, in __init__
    self._using = self._create_connection(
  File "/home/mocheng/anaconda3/envs/py38/lib/python3.8/site-packages/pymilvus/milvus_client/milvus_client.py", line 924, in _create_connection
    raise ex from ex
  File "/home/mocheng/anaconda3/envs/py38/lib/python3.8/site-packages/pymilvus/milvus_client/milvus_client.py", line 921, in _create_connection
    connections.connect(using, user, password, db_name, token, uri=uri, **kwargs)
  File "/home/mocheng/anaconda3/envs/py38/lib/python3.8/site-packages/pymilvus/orm/connections.py", line 461, in connect
    connect_milvus(**kwargs, user=user, password=password, token=token, db_name=db_name)
  File "/home/mocheng/anaconda3/envs/py38/lib/python3.8/site-packages/pymilvus/orm/connections.py", line 411, in connect_milvus
    gh._wait_for_channel_ready(timeout=timeout)
  File "/home/mocheng/anaconda3/envs/py38/lib/python3.8/site-packages/pymilvus/client/grpc_handler.py", line 155, in _wait_for_channel_ready
    raise MilvusException(
pymilvus.exceptions.MilvusException: <MilvusException: (code=2, message=Fail connecting to server on localhost:19530, illegal connection params or server unavailable)>
Command exited with non-zero status 1
	Command being timed: "python -u utils/pymilvus_ivfpq.py redcaps1m 1000000 /mnt/data/mocheng/dataset/redcaps1m/image_embeddings.fvecs /mnt/data/mocheng/dataset/redcaps1m/query.fvecs /mnt/data/mocheng/dataset/redcaps1m/label/sel_1_100000_real/attr_sel_1_100000_real.json /mnt/data/mocheng/dataset/redcaps1m/label/sel_1_100000_real/qrangesel_6_1_100000_real.json /mnt/data/mocheng/dataset/redcaps1m/label/sel_1_100000_real/sif_gt_sel_6_1_100000_real_100.json 100 120 collection_redcaps1m_sel_1_100000_real_512 query 512 512"
	User time (seconds): 2.97
	System time (seconds): 0.13
	Percent of CPU this job got: 28%
	Elapsed (wall clock) time (h:mm:ss or m:ss): 0:10.72
	Average shared text size (kbytes): 0
	Average unshared data size (kbytes): 0
	Average stack size (kbytes): 0
	Average total size (kbytes): 0
	Maximum resident set size (kbytes): 78848
	Average resident set size (kbytes): 0
	Major (requiring I/O) page faults: 28
	Minor (reclaiming a frame) page faults: 22143
	Voluntary context switches: 2185
	Involuntary context switches: 653
	Swaps: 0
	File system inputs: 3280
	File system outputs: 8
	Socket messages sent: 0
	Socket messages received: 0
	Signals delivered: 0
	Page size (bytes): 4096
	Exit status: 1
Start time: 23:27
dataset: redcaps1m
N: 1000000
dataset file: /mnt/data/mocheng/dataset/redcaps1m/image_embeddings.fvecs
query file: /mnt/data/mocheng/dataset/redcaps1m/query.fvecs
attr file: /mnt/data/mocheng/dataset/redcaps1m/label/sel_1_100000_real/attr_sel_1_100000_real.json
query range file: /mnt/data/mocheng/dataset/redcaps1m/label/sel_1_100000_real/qrangesel_10_1_100000_real.json
ground truth file: /mnt/data/mocheng/dataset/redcaps1m/label/sel_1_100000_real/sif_gt_sel_10_1_100000_real_100.json
K: 100
nprobe: 120
collection name: collection_redcaps1m_sel_1_100000_real_512
2025-07-18 14:27:33,932 [ERROR][_create_connection]: Failed to create new connection using: c5a2c8899bc84f7bb12e1a8e904f9464 (milvus_client.py:923)
Traceback (most recent call last):
  File "utils/pymilvus_ivfpq.py", line 67, in <module>
    client = MilvusClient(
  File "/home/mocheng/anaconda3/envs/py38/lib/python3.8/site-packages/pymilvus/milvus_client/milvus_client.py", line 67, in __init__
    self._using = self._create_connection(
  File "/home/mocheng/anaconda3/envs/py38/lib/python3.8/site-packages/pymilvus/milvus_client/milvus_client.py", line 924, in _create_connection
    raise ex from ex
  File "/home/mocheng/anaconda3/envs/py38/lib/python3.8/site-packages/pymilvus/milvus_client/milvus_client.py", line 921, in _create_connection
    connections.connect(using, user, password, db_name, token, uri=uri, **kwargs)
  File "/home/mocheng/anaconda3/envs/py38/lib/python3.8/site-packages/pymilvus/orm/connections.py", line 461, in connect
    connect_milvus(**kwargs, user=user, password=password, token=token, db_name=db_name)
  File "/home/mocheng/anaconda3/envs/py38/lib/python3.8/site-packages/pymilvus/orm/connections.py", line 411, in connect_milvus
    gh._wait_for_channel_ready(timeout=timeout)
  File "/home/mocheng/anaconda3/envs/py38/lib/python3.8/site-packages/pymilvus/client/grpc_handler.py", line 155, in _wait_for_channel_ready
    raise MilvusException(
pymilvus.exceptions.MilvusException: <MilvusException: (code=2, message=Fail connecting to server on localhost:19530, illegal connection params or server unavailable)>
Command exited with non-zero status 1
	Command being timed: "python -u utils/pymilvus_ivfpq.py redcaps1m 1000000 /mnt/data/mocheng/dataset/redcaps1m/image_embeddings.fvecs /mnt/data/mocheng/dataset/redcaps1m/query.fvecs /mnt/data/mocheng/dataset/redcaps1m/label/sel_1_100000_real/attr_sel_1_100000_real.json /mnt/data/mocheng/dataset/redcaps1m/label/sel_1_100000_real/qrangesel_10_1_100000_real.json /mnt/data/mocheng/dataset/redcaps1m/label/sel_1_100000_real/sif_gt_sel_10_1_100000_real_100.json 100 120 collection_redcaps1m_sel_1_100000_real_512 query 512 512"
	User time (seconds): 2.24
	System time (seconds): 0.10
	Percent of CPU this job got: 21%
	Elapsed (wall clock) time (h:mm:ss or m:ss): 0:10.69
	Average shared text size (kbytes): 0
	Average unshared data size (kbytes): 0
	Average stack size (kbytes): 0
	Average total size (kbytes): 0
	Maximum resident set size (kbytes): 76800
	Average resident set size (kbytes): 0
	Major (requiring I/O) page faults: 34
	Minor (reclaiming a frame) page faults: 22127
	Voluntary context switches: 2181
	Involuntary context switches: 607
	Swaps: 0
	File system inputs: 5464
	File system outputs: 24
	Socket messages sent: 0
	Socket messages received: 0
	Signals delivered: 0
	Page size (bytes): 4096
	Exit status: 1
Start time: 23:56
dataset: redcaps1m
N: 1000000
dataset file: /mnt/data/mocheng/dataset/redcaps1m/image_embeddings.fvecs
query file: /mnt/data/mocheng/dataset/redcaps1m/query.fvecs
attr file: /mnt/data/mocheng/dataset/redcaps1m/label/sel_1_100000_real/attr_sel_1_100000_real.json
query range file: /mnt/data/mocheng/dataset/redcaps1m/label/sel_1_100000_real/qrangesel_19_1_100000_real.json
ground truth file: /mnt/data/mocheng/dataset/redcaps1m/label/sel_1_100000_real/sif_gt_sel_19_1_100000_real_100.json
K: 100
nprobe: 120
collection name: collection_redcaps1m_sel_1_100000_real_512
2025-07-18 14:56:15,166 [ERROR][_create_connection]: Failed to create new connection using: 4071bd1489074d6aacfe575c940b3f4d (milvus_client.py:923)
Traceback (most recent call last):
  File "utils/pymilvus_ivfpq.py", line 67, in <module>
    client = MilvusClient(
  File "/home/mocheng/anaconda3/envs/py38/lib/python3.8/site-packages/pymilvus/milvus_client/milvus_client.py", line 67, in __init__
    self._using = self._create_connection(
  File "/home/mocheng/anaconda3/envs/py38/lib/python3.8/site-packages/pymilvus/milvus_client/milvus_client.py", line 924, in _create_connection
    raise ex from ex
  File "/home/mocheng/anaconda3/envs/py38/lib/python3.8/site-packages/pymilvus/milvus_client/milvus_client.py", line 921, in _create_connection
    connections.connect(using, user, password, db_name, token, uri=uri, **kwargs)
  File "/home/mocheng/anaconda3/envs/py38/lib/python3.8/site-packages/pymilvus/orm/connections.py", line 461, in connect
    connect_milvus(**kwargs, user=user, password=password, token=token, db_name=db_name)
  File "/home/mocheng/anaconda3/envs/py38/lib/python3.8/site-packages/pymilvus/orm/connections.py", line 411, in connect_milvus
    gh._wait_for_channel_ready(timeout=timeout)
  File "/home/mocheng/anaconda3/envs/py38/lib/python3.8/site-packages/pymilvus/client/grpc_handler.py", line 155, in _wait_for_channel_ready
    raise MilvusException(
pymilvus.exceptions.MilvusException: <MilvusException: (code=2, message=Fail connecting to server on localhost:19530, illegal connection params or server unavailable)>
Command exited with non-zero status 1
	Command being timed: "python -u utils/pymilvus_ivfpq.py redcaps1m 1000000 /mnt/data/mocheng/dataset/redcaps1m/image_embeddings.fvecs /mnt/data/mocheng/dataset/redcaps1m/query.fvecs /mnt/data/mocheng/dataset/redcaps1m/label/sel_1_100000_real/attr_sel_1_100000_real.json /mnt/data/mocheng/dataset/redcaps1m/label/sel_1_100000_real/qrangesel_19_1_100000_real.json /mnt/data/mocheng/dataset/redcaps1m/label/sel_1_100000_real/sif_gt_sel_19_1_100000_real_100.json 100 120 collection_redcaps1m_sel_1_100000_real_512 query 512 512"
	User time (seconds): 2.91
	System time (seconds): 0.11
	Percent of CPU this job got: 28%
	Elapsed (wall clock) time (h:mm:ss or m:ss): 0:10.54
	Average shared text size (kbytes): 0
	Average unshared data size (kbytes): 0
	Average stack size (kbytes): 0
	Average total size (kbytes): 0
	Maximum resident set size (kbytes): 77824
	Average resident set size (kbytes): 0
	Major (requiring I/O) page faults: 0
	Minor (reclaiming a frame) page faults: 22107
	Voluntary context switches: 1880
	Involuntary context switches: 721
	Swaps: 0
	File system inputs: 0
	File system outputs: 16
	Socket messages sent: 0
	Socket messages received: 0
	Signals delivered: 0
	Page size (bytes): 4096
	Exit status: 1
Start time: 00:15
dataset: redcaps1m
N: 1000000
dataset file: /mnt/data/mocheng/dataset/redcaps1m/image_embeddings.fvecs
query file: /mnt/data/mocheng/dataset/redcaps1m/query.fvecs
attr file: /mnt/data/mocheng/dataset/redcaps1m/label/sel_1_100000_real/attr_sel_1_100000_real.json
query range file: /mnt/data/mocheng/dataset/redcaps1m/label/sel_1_100000_real/qrangesel_20_1_100000_real.json
ground truth file: /mnt/data/mocheng/dataset/redcaps1m/label/sel_1_100000_real/sif_gt_sel_20_1_100000_real_100.json
K: 100
nprobe: 120
collection name: collection_redcaps1m_sel_1_100000_real_512
2025-07-18 15:16:03,151 [ERROR][_create_connection]: Failed to create new connection using: e977fd68a4994da29f7ed49df2e5b100 (milvus_client.py:923)
Traceback (most recent call last):
  File "utils/pymilvus_ivfpq.py", line 67, in <module>
    client = MilvusClient(
  File "/home/mocheng/anaconda3/envs/py38/lib/python3.8/site-packages/pymilvus/milvus_client/milvus_client.py", line 67, in __init__
    self._using = self._create_connection(
  File "/home/mocheng/anaconda3/envs/py38/lib/python3.8/site-packages/pymilvus/milvus_client/milvus_client.py", line 924, in _create_connection
    raise ex from ex
  File "/home/mocheng/anaconda3/envs/py38/lib/python3.8/site-packages/pymilvus/milvus_client/milvus_client.py", line 921, in _create_connection
    connections.connect(using, user, password, db_name, token, uri=uri, **kwargs)
  File "/home/mocheng/anaconda3/envs/py38/lib/python3.8/site-packages/pymilvus/orm/connections.py", line 461, in connect
    connect_milvus(**kwargs, user=user, password=password, token=token, db_name=db_name)
  File "/home/mocheng/anaconda3/envs/py38/lib/python3.8/site-packages/pymilvus/orm/connections.py", line 411, in connect_milvus
    gh._wait_for_channel_ready(timeout=timeout)
  File "/home/mocheng/anaconda3/envs/py38/lib/python3.8/site-packages/pymilvus/client/grpc_handler.py", line 155, in _wait_for_channel_ready
    raise MilvusException(
pymilvus.exceptions.MilvusException: <MilvusException: (code=2, message=Fail connecting to server on localhost:19530, illegal connection params or server unavailable)>
Command exited with non-zero status 1
	Command being timed: "python -u utils/pymilvus_ivfpq.py redcaps1m 1000000 /mnt/data/mocheng/dataset/redcaps1m/image_embeddings.fvecs /mnt/data/mocheng/dataset/redcaps1m/query.fvecs /mnt/data/mocheng/dataset/redcaps1m/label/sel_1_100000_real/attr_sel_1_100000_real.json /mnt/data/mocheng/dataset/redcaps1m/label/sel_1_100000_real/qrangesel_20_1_100000_real.json /mnt/data/mocheng/dataset/redcaps1m/label/sel_1_100000_real/sif_gt_sel_20_1_100000_real_100.json 100 120 collection_redcaps1m_sel_1_100000_real_512 query 512 512"
	User time (seconds): 3.96
	System time (seconds): 0.10
	Percent of CPU this job got: 38%
	Elapsed (wall clock) time (h:mm:ss or m:ss): 0:10.63
	Average shared text size (kbytes): 0
	Average unshared data size (kbytes): 0
	Average stack size (kbytes): 0
	Average total size (kbytes): 0
	Maximum resident set size (kbytes): 76800
	Average resident set size (kbytes): 0
	Major (requiring I/O) page faults: 0
	Minor (reclaiming a frame) page faults: 22116
	Voluntary context switches: 1878
	Involuntary context switches: 559
	Swaps: 0
	File system inputs: 0
	File system outputs: 16
	Socket messages sent: 0
	Socket messages received: 0
	Signals delivered: 0
	Page size (bytes): 4096
	Exit status: 1
