Start time: 04:18
dataset: spacev10m
N: 10000000
dataset file: /mnt/data/mocheng/dataset/spacev10m/base10M.fvecs
query file: /mnt/data/mocheng/dataset/spacev10m/query10k.fvecs
attr file: /mnt/data/mocheng/dataset/spacev10m/label/sel_1_500_random/attr_sel_1_500_random.json
query range file: /mnt/data/mocheng/dataset/spacev10m/label/sel_1_500_random/qrangesel_1_1_500_random_6.json
ground truth file: /mnt/data/mocheng/dataset/spacev10m/label/sel_1_500_random/sif_gt_sel_1_1_500_random_6_100.json
K: 100
nprobe: 150
collection name: collection_spacev10m_sel_1_500_random_50
2025-07-12 19:18:14,807 [ERROR][_create_connection]: Failed to create new connection using: b18ab2cd27334d808c0334e59c54ac96 (milvus_client.py:923)
Traceback (most recent call last):
  File "utils/pymilvus_ivfpq.py", line 67, in <module>
    client = MilvusClient(
  File "/home/mocheng/anaconda3/envs/py38/lib/python3.8/site-packages/pymilvus/milvus_client/milvus_client.py", line 67, in __init__
    self._using = self._create_connection(
  File "/home/mocheng/anaconda3/envs/py38/lib/python3.8/site-packages/pymilvus/milvus_client/milvus_client.py", line 924, in _create_connection
    raise ex from ex
  File "/home/mocheng/anaconda3/envs/py38/lib/python3.8/site-packages/pymilvus/milvus_client/milvus_client.py", line 921, in _create_connection
    connections.connect(using, user, password, db_name, token, uri=uri, **kwargs)
  File "/home/mocheng/anaconda3/envs/py38/lib/python3.8/site-packages/pymilvus/orm/connections.py", line 461, in connect
    connect_milvus(**kwargs, user=user, password=password, token=token, db_name=db_name)
  File "/home/mocheng/anaconda3/envs/py38/lib/python3.8/site-packages/pymilvus/orm/connections.py", line 411, in connect_milvus
    gh._wait_for_channel_ready(timeout=timeout)
  File "/home/mocheng/anaconda3/envs/py38/lib/python3.8/site-packages/pymilvus/client/grpc_handler.py", line 155, in _wait_for_channel_ready
    raise MilvusException(
pymilvus.exceptions.MilvusException: <MilvusException: (code=2, message=Fail connecting to server on localhost:19530, illegal connection params or server unavailable)>
Command exited with non-zero status 1
	Command being timed: "python -u utils/pymilvus_ivfpq.py spacev10m 10000000 /mnt/data/mocheng/dataset/spacev10m/base10M.fvecs /mnt/data/mocheng/dataset/spacev10m/query10k.fvecs /mnt/data/mocheng/dataset/spacev10m/label/sel_1_500_random/attr_sel_1_500_random.json /mnt/data/mocheng/dataset/spacev10m/label/sel_1_500_random/qrangesel_1_1_500_random_6.json /mnt/data/mocheng/dataset/spacev10m/label/sel_1_500_random/sif_gt_sel_1_1_500_random_6_100.json 100 150 collection_spacev10m_sel_1_500_random_50 query 50 100"
	User time (seconds): 2.13
	System time (seconds): 0.11
	Percent of CPU this job got: 21%
	Elapsed (wall clock) time (h:mm:ss or m:ss): 0:10.57
	Average shared text size (kbytes): 0
	Average unshared data size (kbytes): 0
	Average stack size (kbytes): 0
	Average total size (kbytes): 0
	Maximum resident set size (kbytes): 78848
	Average resident set size (kbytes): 0
	Major (requiring I/O) page faults: 0
	Minor (reclaiming a frame) page faults: 22127
	Voluntary context switches: 1910
	Involuntary context switches: 552
	Swaps: 0
	File system inputs: 0
	File system outputs: 8
	Socket messages sent: 0
	Socket messages received: 0
	Signals delivered: 0
	Page size (bytes): 4096
	Exit status: 1
Start time: 04:46
dataset: spacev10m
N: 10000000
dataset file: /mnt/data/mocheng/dataset/spacev10m/base10M.fvecs
query file: /mnt/data/mocheng/dataset/spacev10m/query10k.fvecs
attr file: /mnt/data/mocheng/dataset/spacev10m/label/sel_1_500_random/attr_sel_1_500_random.json
query range file: /mnt/data/mocheng/dataset/spacev10m/label/sel_1_500_random/qrangesel_1_1_500_random_10.json
ground truth file: /mnt/data/mocheng/dataset/spacev10m/label/sel_1_500_random/sif_gt_sel_1_1_500_random_10_100.json
K: 100
nprobe: 150
collection name: collection_spacev10m_sel_1_500_random_50
2025-07-12 19:46:39,511 [ERROR][_create_connection]: Failed to create new connection using: c61300ecc2d94c4daa215a190b1782e0 (milvus_client.py:923)
Traceback (most recent call last):
  File "utils/pymilvus_ivfpq.py", line 67, in <module>
    client = MilvusClient(
  File "/home/mocheng/anaconda3/envs/py38/lib/python3.8/site-packages/pymilvus/milvus_client/milvus_client.py", line 67, in __init__
    self._using = self._create_connection(
  File "/home/mocheng/anaconda3/envs/py38/lib/python3.8/site-packages/pymilvus/milvus_client/milvus_client.py", line 924, in _create_connection
    raise ex from ex
  File "/home/mocheng/anaconda3/envs/py38/lib/python3.8/site-packages/pymilvus/milvus_client/milvus_client.py", line 921, in _create_connection
    connections.connect(using, user, password, db_name, token, uri=uri, **kwargs)
  File "/home/mocheng/anaconda3/envs/py38/lib/python3.8/site-packages/pymilvus/orm/connections.py", line 461, in connect
    connect_milvus(**kwargs, user=user, password=password, token=token, db_name=db_name)
  File "/home/mocheng/anaconda3/envs/py38/lib/python3.8/site-packages/pymilvus/orm/connections.py", line 411, in connect_milvus
    gh._wait_for_channel_ready(timeout=timeout)
  File "/home/mocheng/anaconda3/envs/py38/lib/python3.8/site-packages/pymilvus/client/grpc_handler.py", line 155, in _wait_for_channel_ready
    raise MilvusException(
pymilvus.exceptions.MilvusException: <MilvusException: (code=2, message=Fail connecting to server on localhost:19530, illegal connection params or server unavailable)>
Command exited with non-zero status 1
	Command being timed: "python -u utils/pymilvus_ivfpq.py spacev10m 10000000 /mnt/data/mocheng/dataset/spacev10m/base10M.fvecs /mnt/data/mocheng/dataset/spacev10m/query10k.fvecs /mnt/data/mocheng/dataset/spacev10m/label/sel_1_500_random/attr_sel_1_500_random.json /mnt/data/mocheng/dataset/spacev10m/label/sel_1_500_random/qrangesel_1_1_500_random_10.json /mnt/data/mocheng/dataset/spacev10m/label/sel_1_500_random/sif_gt_sel_1_1_500_random_10_100.json 100 150 collection_spacev10m_sel_1_500_random_50 query 50 100"
	User time (seconds): 2.88
	System time (seconds): 0.08
	Percent of CPU this job got: 28%
	Elapsed (wall clock) time (h:mm:ss or m:ss): 0:10.60
	Average shared text size (kbytes): 0
	Average unshared data size (kbytes): 0
	Average stack size (kbytes): 0
	Average total size (kbytes): 0
	Maximum resident set size (kbytes): 77824
	Average resident set size (kbytes): 0
	Major (requiring I/O) page faults: 1
	Minor (reclaiming a frame) page faults: 22102
	Voluntary context switches: 1926
	Involuntary context switches: 626
	Swaps: 0
	File system inputs: 0
	File system outputs: 16
	Socket messages sent: 0
	Socket messages received: 0
	Signals delivered: 0
	Page size (bytes): 4096
	Exit status: 1
Start time: 05:12
dataset: spacev10m
N: 10000000
dataset file: /mnt/data/mocheng/dataset/spacev10m/base10M.fvecs
query file: /mnt/data/mocheng/dataset/spacev10m/query10k.fvecs
attr file: /mnt/data/mocheng/dataset/spacev10m/label/sel_1_500_random/attr_sel_1_500_random.json
query range file: /mnt/data/mocheng/dataset/spacev10m/label/sel_1_500_random/qrangesel_1_1_500_random_19.json
ground truth file: /mnt/data/mocheng/dataset/spacev10m/label/sel_1_500_random/sif_gt_sel_1_1_500_random_19_100.json
K: 100
nprobe: 150
collection name: collection_spacev10m_sel_1_500_random_50
2025-07-12 20:12:55,343 [ERROR][_create_connection]: Failed to create new connection using: e5c0822f0a0e47b4a392879ee685f88a (milvus_client.py:923)
Traceback (most recent call last):
  File "utils/pymilvus_ivfpq.py", line 67, in <module>
    client = MilvusClient(
  File "/home/mocheng/anaconda3/envs/py38/lib/python3.8/site-packages/pymilvus/milvus_client/milvus_client.py", line 67, in __init__
    self._using = self._create_connection(
  File "/home/mocheng/anaconda3/envs/py38/lib/python3.8/site-packages/pymilvus/milvus_client/milvus_client.py", line 924, in _create_connection
    raise ex from ex
  File "/home/mocheng/anaconda3/envs/py38/lib/python3.8/site-packages/pymilvus/milvus_client/milvus_client.py", line 921, in _create_connection
    connections.connect(using, user, password, db_name, token, uri=uri, **kwargs)
  File "/home/mocheng/anaconda3/envs/py38/lib/python3.8/site-packages/pymilvus/orm/connections.py", line 461, in connect
    connect_milvus(**kwargs, user=user, password=password, token=token, db_name=db_name)
  File "/home/mocheng/anaconda3/envs/py38/lib/python3.8/site-packages/pymilvus/orm/connections.py", line 411, in connect_milvus
    gh._wait_for_channel_ready(timeout=timeout)
  File "/home/mocheng/anaconda3/envs/py38/lib/python3.8/site-packages/pymilvus/client/grpc_handler.py", line 155, in _wait_for_channel_ready
    raise MilvusException(
pymilvus.exceptions.MilvusException: <MilvusException: (code=2, message=Fail connecting to server on localhost:19530, illegal connection params or server unavailable)>
Command exited with non-zero status 1
	Command being timed: "python -u utils/pymilvus_ivfpq.py spacev10m 10000000 /mnt/data/mocheng/dataset/spacev10m/base10M.fvecs /mnt/data/mocheng/dataset/spacev10m/query10k.fvecs /mnt/data/mocheng/dataset/spacev10m/label/sel_1_500_random/attr_sel_1_500_random.json /mnt/data/mocheng/dataset/spacev10m/label/sel_1_500_random/qrangesel_1_1_500_random_19.json /mnt/data/mocheng/dataset/spacev10m/label/sel_1_500_random/sif_gt_sel_1_1_500_random_19_100.json 100 150 collection_spacev10m_sel_1_500_random_50 query 50 100"
	User time (seconds): 1.87
	System time (seconds): 0.13
	Percent of CPU this job got: 18%
	Elapsed (wall clock) time (h:mm:ss or m:ss): 0:10.92
	Average shared text size (kbytes): 0
	Average unshared data size (kbytes): 0
	Average stack size (kbytes): 0
	Average total size (kbytes): 0
	Maximum resident set size (kbytes): 71676
	Average resident set size (kbytes): 0
	Major (requiring I/O) page faults: 20
	Minor (reclaiming a frame) page faults: 22161
	Voluntary context switches: 2487
	Involuntary context switches: 369
	Swaps: 0
	File system inputs: 2896
	File system outputs: 16
	Socket messages sent: 0
	Socket messages received: 0
	Signals delivered: 0
	Page size (bytes): 4096
	Exit status: 1
Start time: 05:39
dataset: spacev10m
N: 10000000
dataset file: /mnt/data/mocheng/dataset/spacev10m/base10M.fvecs
query file: /mnt/data/mocheng/dataset/spacev10m/query10k.fvecs
attr file: /mnt/data/mocheng/dataset/spacev10m/label/sel_1_500_random/attr_sel_1_500_random.json
query range file: /mnt/data/mocheng/dataset/spacev10m/label/sel_1_500_random/qrangesel_1_1_500_random_20.json
ground truth file: /mnt/data/mocheng/dataset/spacev10m/label/sel_1_500_random/sif_gt_sel_1_1_500_random_20_100.json
K: 100
nprobe: 150
collection name: collection_spacev10m_sel_1_500_random_50
2025-07-12 20:39:54,533 [ERROR][_create_connection]: Failed to create new connection using: 892a011548eb40abbac0129734df6b5f (milvus_client.py:923)
Traceback (most recent call last):
  File "utils/pymilvus_ivfpq.py", line 67, in <module>
    client = MilvusClient(
  File "/home/mocheng/anaconda3/envs/py38/lib/python3.8/site-packages/pymilvus/milvus_client/milvus_client.py", line 67, in __init__
    self._using = self._create_connection(
  File "/home/mocheng/anaconda3/envs/py38/lib/python3.8/site-packages/pymilvus/milvus_client/milvus_client.py", line 924, in _create_connection
    raise ex from ex
  File "/home/mocheng/anaconda3/envs/py38/lib/python3.8/site-packages/pymilvus/milvus_client/milvus_client.py", line 921, in _create_connection
    connections.connect(using, user, password, db_name, token, uri=uri, **kwargs)
  File "/home/mocheng/anaconda3/envs/py38/lib/python3.8/site-packages/pymilvus/orm/connections.py", line 461, in connect
    connect_milvus(**kwargs, user=user, password=password, token=token, db_name=db_name)
  File "/home/mocheng/anaconda3/envs/py38/lib/python3.8/site-packages/pymilvus/orm/connections.py", line 411, in connect_milvus
    gh._wait_for_channel_ready(timeout=timeout)
  File "/home/mocheng/anaconda3/envs/py38/lib/python3.8/site-packages/pymilvus/client/grpc_handler.py", line 155, in _wait_for_channel_ready
    raise MilvusException(
pymilvus.exceptions.MilvusException: <MilvusException: (code=2, message=Fail connecting to server on localhost:19530, illegal connection params or server unavailable)>
Command exited with non-zero status 1
	Command being timed: "python -u utils/pymilvus_ivfpq.py spacev10m 10000000 /mnt/data/mocheng/dataset/spacev10m/base10M.fvecs /mnt/data/mocheng/dataset/spacev10m/query10k.fvecs /mnt/data/mocheng/dataset/spacev10m/label/sel_1_500_random/attr_sel_1_500_random.json /mnt/data/mocheng/dataset/spacev10m/label/sel_1_500_random/qrangesel_1_1_500_random_20.json /mnt/data/mocheng/dataset/spacev10m/label/sel_1_500_random/sif_gt_sel_1_1_500_random_20_100.json 100 150 collection_spacev10m_sel_1_500_random_50 query 50 100"
	User time (seconds): 2.12
	System time (seconds): 0.07
	Percent of CPU this job got: 20%
	Elapsed (wall clock) time (h:mm:ss or m:ss): 0:10.53
	Average shared text size (kbytes): 0
	Average unshared data size (kbytes): 0
	Average stack size (kbytes): 0
	Average total size (kbytes): 0
	Maximum resident set size (kbytes): 77820
	Average resident set size (kbytes): 0
	Major (requiring I/O) page faults: 0
	Minor (reclaiming a frame) page faults: 22122
	Voluntary context switches: 1904
	Involuntary context switches: 492
	Swaps: 0
	File system inputs: 0
	File system outputs: 8
	Socket messages sent: 0
	Socket messages received: 0
	Signals delivered: 0
	Page size (bytes): 4096
	Exit status: 1
