Start time: 22:13
dataset: redcaps1m
N: 1000000
dataset file: /mnt/data/mocheng/dataset/redcaps1m/image_embeddings.fvecs
query file: /mnt/data/mocheng/dataset/redcaps1m/query.fvecs
attr file: /mnt/data/mocheng/dataset/redcaps1m/label/sel_1_100000_real/attr_sel_1_100000_real.json
query range file: /mnt/data/mocheng/dataset/redcaps1m/label/sel_1_100000_real/qrangesel_6_1_100000_real.json
ground truth file: /mnt/data/mocheng/dataset/redcaps1m/label/sel_1_100000_real/sif_gt_sel_6_1_100000_real_100.json
K: 100
M: 40
ef_construction: 1000
ef_search: 150
distribution: sel_1_100000_real
collection name: collection_hnsw_redcaps1m_sel_1_100000_real_efc1000
mode: query
d: 512
2025-07-18 13:13:27,193 [ERROR][_create_connection]: Failed to create new connection using: c2906046d39c48eb9cdcb9cc09aa693f (milvus_client.py:923)
Traceback (most recent call last):
  File "utils/pymilvus_hnsw.py", line 75, in <module>
    client = MilvusClient(
  File "/home/mocheng/anaconda3/envs/py38/lib/python3.8/site-packages/pymilvus/milvus_client/milvus_client.py", line 67, in __init__
    self._using = self._create_connection(
  File "/home/mocheng/anaconda3/envs/py38/lib/python3.8/site-packages/pymilvus/milvus_client/milvus_client.py", line 924, in _create_connection
    raise ex from ex
  File "/home/mocheng/anaconda3/envs/py38/lib/python3.8/site-packages/pymilvus/milvus_client/milvus_client.py", line 921, in _create_connection
    connections.connect(using, user, password, db_name, token, uri=uri, **kwargs)
  File "/home/mocheng/anaconda3/envs/py38/lib/python3.8/site-packages/pymilvus/orm/connections.py", line 461, in connect
    connect_milvus(**kwargs, user=user, password=password, token=token, db_name=db_name)
  File "/home/mocheng/anaconda3/envs/py38/lib/python3.8/site-packages/pymilvus/orm/connections.py", line 411, in connect_milvus
    gh._wait_for_channel_ready(timeout=timeout)
  File "/home/mocheng/anaconda3/envs/py38/lib/python3.8/site-packages/pymilvus/client/grpc_handler.py", line 155, in _wait_for_channel_ready
    raise MilvusException(
pymilvus.exceptions.MilvusException: <MilvusException: (code=2, message=Fail connecting to server on localhost:19530, illegal connection params or server unavailable)>
Command exited with non-zero status 1
	Command being timed: "python -u utils/pymilvus_hnsw.py redcaps1m 1000000 /mnt/data/mocheng/dataset/redcaps1m/image_embeddings.fvecs /mnt/data/mocheng/dataset/redcaps1m/query.fvecs /mnt/data/mocheng/dataset/redcaps1m/label/sel_1_100000_real/attr_sel_1_100000_real.json /mnt/data/mocheng/dataset/redcaps1m/label/sel_1_100000_real/qrangesel_6_1_100000_real.json /mnt/data/mocheng/dataset/redcaps1m/label/sel_1_100000_real/sif_gt_sel_6_1_100000_real_100.json 100 40 1000 150 sel_1_100000_real collection_hnsw_redcaps1m_sel_1_100000_real_efc1000 query 512"
	User time (seconds): 5.66
	System time (seconds): 0.12
	Percent of CPU this job got: 54%
	Elapsed (wall clock) time (h:mm:ss or m:ss): 0:10.65
	Average shared text size (kbytes): 0
	Average unshared data size (kbytes): 0
	Average stack size (kbytes): 0
	Average total size (kbytes): 0
	Maximum resident set size (kbytes): 77824
	Average resident set size (kbytes): 0
	Major (requiring I/O) page faults: 0
	Minor (reclaiming a frame) page faults: 22141
	Voluntary context switches: 1905
	Involuntary context switches: 815
	Swaps: 0
	File system inputs: 0
	File system outputs: 8
	Socket messages sent: 0
	Socket messages received: 0
	Signals delivered: 0
	Page size (bytes): 4096
	Exit status: 1
Start time: 23:27
dataset: redcaps1m
N: 1000000
dataset file: /mnt/data/mocheng/dataset/redcaps1m/image_embeddings.fvecs
query file: /mnt/data/mocheng/dataset/redcaps1m/query.fvecs
attr file: /mnt/data/mocheng/dataset/redcaps1m/label/sel_1_100000_real/attr_sel_1_100000_real.json
query range file: /mnt/data/mocheng/dataset/redcaps1m/label/sel_1_100000_real/qrangesel_10_1_100000_real.json
ground truth file: /mnt/data/mocheng/dataset/redcaps1m/label/sel_1_100000_real/sif_gt_sel_10_1_100000_real_100.json
K: 100
M: 40
ef_construction: 1000
ef_search: 150
distribution: sel_1_100000_real
collection name: collection_hnsw_redcaps1m_sel_1_100000_real_efc1000
mode: query
d: 512
2025-07-18 14:27:44,677 [ERROR][_create_connection]: Failed to create new connection using: 37b296ca8d494ffa995eb6eb877d46bb (milvus_client.py:923)
Traceback (most recent call last):
  File "utils/pymilvus_hnsw.py", line 75, in <module>
    client = MilvusClient(
  File "/home/mocheng/anaconda3/envs/py38/lib/python3.8/site-packages/pymilvus/milvus_client/milvus_client.py", line 67, in __init__
    self._using = self._create_connection(
  File "/home/mocheng/anaconda3/envs/py38/lib/python3.8/site-packages/pymilvus/milvus_client/milvus_client.py", line 924, in _create_connection
    raise ex from ex
  File "/home/mocheng/anaconda3/envs/py38/lib/python3.8/site-packages/pymilvus/milvus_client/milvus_client.py", line 921, in _create_connection
    connections.connect(using, user, password, db_name, token, uri=uri, **kwargs)
  File "/home/mocheng/anaconda3/envs/py38/lib/python3.8/site-packages/pymilvus/orm/connections.py", line 461, in connect
    connect_milvus(**kwargs, user=user, password=password, token=token, db_name=db_name)
  File "/home/mocheng/anaconda3/envs/py38/lib/python3.8/site-packages/pymilvus/orm/connections.py", line 411, in connect_milvus
    gh._wait_for_channel_ready(timeout=timeout)
  File "/home/mocheng/anaconda3/envs/py38/lib/python3.8/site-packages/pymilvus/client/grpc_handler.py", line 155, in _wait_for_channel_ready
    raise MilvusException(
pymilvus.exceptions.MilvusException: <MilvusException: (code=2, message=Fail connecting to server on localhost:19530, illegal connection params or server unavailable)>
Command exited with non-zero status 1
	Command being timed: "python -u utils/pymilvus_hnsw.py redcaps1m 1000000 /mnt/data/mocheng/dataset/redcaps1m/image_embeddings.fvecs /mnt/data/mocheng/dataset/redcaps1m/query.fvecs /mnt/data/mocheng/dataset/redcaps1m/label/sel_1_100000_real/attr_sel_1_100000_real.json /mnt/data/mocheng/dataset/redcaps1m/label/sel_1_100000_real/qrangesel_10_1_100000_real.json /mnt/data/mocheng/dataset/redcaps1m/label/sel_1_100000_real/sif_gt_sel_10_1_100000_real_100.json 100 40 1000 150 sel_1_100000_real collection_hnsw_redcaps1m_sel_1_100000_real_efc1000 query 512"
	User time (seconds): 6.15
	System time (seconds): 0.10
	Percent of CPU this job got: 58%
	Elapsed (wall clock) time (h:mm:ss or m:ss): 0:10.69
	Average shared text size (kbytes): 0
	Average unshared data size (kbytes): 0
	Average stack size (kbytes): 0
	Average total size (kbytes): 0
	Maximum resident set size (kbytes): 79872
	Average resident set size (kbytes): 0
	Major (requiring I/O) page faults: 0
	Minor (reclaiming a frame) page faults: 22135
	Voluntary context switches: 1865
	Involuntary context switches: 702
	Swaps: 0
	File system inputs: 0
	File system outputs: 16
	Socket messages sent: 0
	Socket messages received: 0
	Signals delivered: 0
	Page size (bytes): 4096
	Exit status: 1
Start time: 23:56
dataset: redcaps1m
N: 1000000
dataset file: /mnt/data/mocheng/dataset/redcaps1m/image_embeddings.fvecs
query file: /mnt/data/mocheng/dataset/redcaps1m/query.fvecs
attr file: /mnt/data/mocheng/dataset/redcaps1m/label/sel_1_100000_real/attr_sel_1_100000_real.json
query range file: /mnt/data/mocheng/dataset/redcaps1m/label/sel_1_100000_real/qrangesel_19_1_100000_real.json
ground truth file: /mnt/data/mocheng/dataset/redcaps1m/label/sel_1_100000_real/sif_gt_sel_19_1_100000_real_100.json
K: 100
M: 40
ef_construction: 1000
ef_search: 150
distribution: sel_1_100000_real
collection name: collection_hnsw_redcaps1m_sel_1_100000_real_efc1000
mode: query
d: 512
2025-07-18 14:56:25,902 [ERROR][_create_connection]: Failed to create new connection using: ea48dca0ddb84f2c873399eb0f614d1f (milvus_client.py:923)
Traceback (most recent call last):
  File "utils/pymilvus_hnsw.py", line 75, in <module>
    client = MilvusClient(
  File "/home/mocheng/anaconda3/envs/py38/lib/python3.8/site-packages/pymilvus/milvus_client/milvus_client.py", line 67, in __init__
    self._using = self._create_connection(
  File "/home/mocheng/anaconda3/envs/py38/lib/python3.8/site-packages/pymilvus/milvus_client/milvus_client.py", line 924, in _create_connection
    raise ex from ex
  File "/home/mocheng/anaconda3/envs/py38/lib/python3.8/site-packages/pymilvus/milvus_client/milvus_client.py", line 921, in _create_connection
    connections.connect(using, user, password, db_name, token, uri=uri, **kwargs)
  File "/home/mocheng/anaconda3/envs/py38/lib/python3.8/site-packages/pymilvus/orm/connections.py", line 461, in connect
    connect_milvus(**kwargs, user=user, password=password, token=token, db_name=db_name)
  File "/home/mocheng/anaconda3/envs/py38/lib/python3.8/site-packages/pymilvus/orm/connections.py", line 411, in connect_milvus
    gh._wait_for_channel_ready(timeout=timeout)
  File "/home/mocheng/anaconda3/envs/py38/lib/python3.8/site-packages/pymilvus/client/grpc_handler.py", line 155, in _wait_for_channel_ready
    raise MilvusException(
pymilvus.exceptions.MilvusException: <MilvusException: (code=2, message=Fail connecting to server on localhost:19530, illegal connection params or server unavailable)>
Command exited with non-zero status 1
	Command being timed: "python -u utils/pymilvus_hnsw.py redcaps1m 1000000 /mnt/data/mocheng/dataset/redcaps1m/image_embeddings.fvecs /mnt/data/mocheng/dataset/redcaps1m/query.fvecs /mnt/data/mocheng/dataset/redcaps1m/label/sel_1_100000_real/attr_sel_1_100000_real.json /mnt/data/mocheng/dataset/redcaps1m/label/sel_1_100000_real/qrangesel_19_1_100000_real.json /mnt/data/mocheng/dataset/redcaps1m/label/sel_1_100000_real/sif_gt_sel_19_1_100000_real_100.json 100 40 1000 150 sel_1_100000_real collection_hnsw_redcaps1m_sel_1_100000_real_efc1000 query 512"
	User time (seconds): 1.91
	System time (seconds): 0.10
	Percent of CPU this job got: 18%
	Elapsed (wall clock) time (h:mm:ss or m:ss): 0:10.61
	Average shared text size (kbytes): 0
	Average unshared data size (kbytes): 0
	Average stack size (kbytes): 0
	Average total size (kbytes): 0
	Maximum resident set size (kbytes): 78848
	Average resident set size (kbytes): 0
	Major (requiring I/O) page faults: 0
	Minor (reclaiming a frame) page faults: 22118
	Voluntary context switches: 1909
	Involuntary context switches: 423
	Swaps: 0
	File system inputs: 0
	File system outputs: 16
	Socket messages sent: 0
	Socket messages received: 0
	Signals delivered: 0
	Page size (bytes): 4096
	Exit status: 1
Start time: 00:16
dataset: redcaps1m
N: 1000000
dataset file: /mnt/data/mocheng/dataset/redcaps1m/image_embeddings.fvecs
query file: /mnt/data/mocheng/dataset/redcaps1m/query.fvecs
attr file: /mnt/data/mocheng/dataset/redcaps1m/label/sel_1_100000_real/attr_sel_1_100000_real.json
query range file: /mnt/data/mocheng/dataset/redcaps1m/label/sel_1_100000_real/qrangesel_20_1_100000_real.json
ground truth file: /mnt/data/mocheng/dataset/redcaps1m/label/sel_1_100000_real/sif_gt_sel_20_1_100000_real_100.json
K: 100
M: 40
ef_construction: 1000
ef_search: 150
distribution: sel_1_100000_real
collection name: collection_hnsw_redcaps1m_sel_1_100000_real_efc1000
mode: query
d: 512
2025-07-18 15:16:13,893 [ERROR][_create_connection]: Failed to create new connection using: 616a93ad2b59453c833bdd7174581629 (milvus_client.py:923)
Traceback (most recent call last):
  File "utils/pymilvus_hnsw.py", line 75, in <module>
    client = MilvusClient(
  File "/home/mocheng/anaconda3/envs/py38/lib/python3.8/site-packages/pymilvus/milvus_client/milvus_client.py", line 67, in __init__
    self._using = self._create_connection(
  File "/home/mocheng/anaconda3/envs/py38/lib/python3.8/site-packages/pymilvus/milvus_client/milvus_client.py", line 924, in _create_connection
    raise ex from ex
  File "/home/mocheng/anaconda3/envs/py38/lib/python3.8/site-packages/pymilvus/milvus_client/milvus_client.py", line 921, in _create_connection
    connections.connect(using, user, password, db_name, token, uri=uri, **kwargs)
  File "/home/mocheng/anaconda3/envs/py38/lib/python3.8/site-packages/pymilvus/orm/connections.py", line 461, in connect
    connect_milvus(**kwargs, user=user, password=password, token=token, db_name=db_name)
  File "/home/mocheng/anaconda3/envs/py38/lib/python3.8/site-packages/pymilvus/orm/connections.py", line 411, in connect_milvus
    gh._wait_for_channel_ready(timeout=timeout)
  File "/home/mocheng/anaconda3/envs/py38/lib/python3.8/site-packages/pymilvus/client/grpc_handler.py", line 155, in _wait_for_channel_ready
    raise MilvusException(
pymilvus.exceptions.MilvusException: <MilvusException: (code=2, message=Fail connecting to server on localhost:19530, illegal connection params or server unavailable)>
Command exited with non-zero status 1
	Command being timed: "python -u utils/pymilvus_hnsw.py redcaps1m 1000000 /mnt/data/mocheng/dataset/redcaps1m/image_embeddings.fvecs /mnt/data/mocheng/dataset/redcaps1m/query.fvecs /mnt/data/mocheng/dataset/redcaps1m/label/sel_1_100000_real/attr_sel_1_100000_real.json /mnt/data/mocheng/dataset/redcaps1m/label/sel_1_100000_real/qrangesel_20_1_100000_real.json /mnt/data/mocheng/dataset/redcaps1m/label/sel_1_100000_real/sif_gt_sel_20_1_100000_real_100.json 100 40 1000 150 sel_1_100000_real collection_hnsw_redcaps1m_sel_1_100000_real_efc1000 query 512"
	User time (seconds): 2.09
	System time (seconds): 0.09
	Percent of CPU this job got: 20%
	Elapsed (wall clock) time (h:mm:ss or m:ss): 0:10.69
	Average shared text size (kbytes): 0
	Average unshared data size (kbytes): 0
	Average stack size (kbytes): 0
	Average total size (kbytes): 0
	Maximum resident set size (kbytes): 78848
	Average resident set size (kbytes): 0
	Major (requiring I/O) page faults: 0
	Minor (reclaiming a frame) page faults: 22125
	Voluntary context switches: 1880
	Involuntary context switches: 507
	Swaps: 0
	File system inputs: 0
	File system outputs: 16
	Socket messages sent: 0
	Socket messages received: 0
	Signals delivered: 0
	Page size (bytes): 4096
	Exit status: 1
