Start time: 08:54
dataset: deep10m
N: 10000000
dataset file: /mnt/data/mocheng/dataset/deep10m/base.10M.fvecs
query file: /mnt/data/mocheng/dataset/deep10m/query.public.10K.fvecs
attr file: /mnt/data/mocheng/dataset/deep10m/label/sel_1_100000_random/attr_sel_1_100000_random.json
query range file: /mnt/data/mocheng/dataset/deep10m/label/sel_1_100000_random/qrangesel_7000_1_100000_random.json
ground truth file: /mnt/data/mocheng/dataset/deep10m/label/sel_1_100000_random/sif_gt_sel_7000_1_100000_random_10.json
K: 10
M: 40
ef_construction: 1000
ef_search: 1000
distribution: sel_1_100000_random
collection name: collection_hnsw_deep10m_sel_1_100000_random_efc1000
mode: query
d: 96
Failed to create new connection using: 0e6f4bb1e3e94a4596bde315eca9a183
Traceback (most recent call last):
  File "utils/pymilvus_hnsw.py", line 75, in <module>
    client = MilvusClient(
  File "/home/mocheng/anaconda3/envs/py38/lib/python3.8/site-packages/pymilvus/milvus_client/milvus_client.py", line 60, in __init__
    self._using = self._create_connection(
  File "/home/mocheng/anaconda3/envs/py38/lib/python3.8/site-packages/pymilvus/milvus_client/milvus_client.py", line 728, in _create_connection
    raise ex from ex
  File "/home/mocheng/anaconda3/envs/py38/lib/python3.8/site-packages/pymilvus/milvus_client/milvus_client.py", line 725, in _create_connection
    connections.connect(using, user, password, db_name, token, uri=uri, **kwargs)
  File "/home/mocheng/anaconda3/envs/py38/lib/python3.8/site-packages/pymilvus/orm/connections.py", line 449, in connect
    connect_milvus(**kwargs, user=user, password=password, token=token, db_name=db_name)
  File "/home/mocheng/anaconda3/envs/py38/lib/python3.8/site-packages/pymilvus/orm/connections.py", line 400, in connect_milvus
    gh._wait_for_channel_ready(timeout=timeout)
  File "/home/mocheng/anaconda3/envs/py38/lib/python3.8/site-packages/pymilvus/client/grpc_handler.py", line 150, in _wait_for_channel_ready
    raise MilvusException(
pymilvus.exceptions.MilvusException: <MilvusException: (code=2, message=Fail connecting to server on localhost:19530, illegal connection params or server unavailable)>
Command exited with non-zero status 1
	Command being timed: "python -u utils/pymilvus_hnsw.py deep10m 10000000 /mnt/data/mocheng/dataset/deep10m/base.10M.fvecs /mnt/data/mocheng/dataset/deep10m/query.public.10K.fvecs /mnt/data/mocheng/dataset/deep10m/label/sel_1_100000_random/attr_sel_1_100000_random.json /mnt/data/mocheng/dataset/deep10m/label/sel_1_100000_random/qrangesel_7000_1_100000_random.json /mnt/data/mocheng/dataset/deep10m/label/sel_1_100000_random/sif_gt_sel_7000_1_100000_random_10.json 10 40 1000 1000 sel_1_100000_random collection_hnsw_deep10m_sel_1_100000_random_efc1000 query 96"
	User time (seconds): 13.48
	System time (seconds): 0.09
	Percent of CPU this job got: 130%
	Elapsed (wall clock) time (h:mm:ss or m:ss): 0:10.39
	Average shared text size (kbytes): 0
	Average unshared data size (kbytes): 0
	Average stack size (kbytes): 0
	Average total size (kbytes): 0
	Maximum resident set size (kbytes): 82944
	Average resident set size (kbytes): 0
	Major (requiring I/O) page faults: 0
	Minor (reclaiming a frame) page faults: 18375
	Voluntary context switches: 1959
	Involuntary context switches: 166
	Swaps: 0
	File system inputs: 0
	File system outputs: 8
	Socket messages sent: 0
	Socket messages received: 0
	Signals delivered: 0
	Page size (bytes): 4096
	Exit status: 1
Start time: 11:05
dataset: deep10m
N: 10000000
dataset file: /mnt/data/mocheng/dataset/deep10m/base.10M.fvecs
query file: /mnt/data/mocheng/dataset/deep10m/query.public.10K.fvecs
attr file: /mnt/data/mocheng/dataset/deep10m/label/sel_1_100000_random/attr_sel_1_100000_random.json
query range file: /mnt/data/mocheng/dataset/deep10m/label/sel_1_100000_random/qrangesel_8000_1_100000_random.json
ground truth file: /mnt/data/mocheng/dataset/deep10m/label/sel_1_100000_random/sif_gt_sel_8000_1_100000_random_10.json
K: 10
M: 40
ef_construction: 1000
ef_search: 1000
distribution: sel_1_100000_random
collection name: collection_hnsw_deep10m_sel_1_100000_random_efc1000
mode: query
d: 96
Failed to create new connection using: 6fbd0d4b38fb444ca330cb9a409c1194
Traceback (most recent call last):
  File "utils/pymilvus_hnsw.py", line 75, in <module>
    client = MilvusClient(
  File "/home/mocheng/anaconda3/envs/py38/lib/python3.8/site-packages/pymilvus/milvus_client/milvus_client.py", line 60, in __init__
    self._using = self._create_connection(
  File "/home/mocheng/anaconda3/envs/py38/lib/python3.8/site-packages/pymilvus/milvus_client/milvus_client.py", line 728, in _create_connection
    raise ex from ex
  File "/home/mocheng/anaconda3/envs/py38/lib/python3.8/site-packages/pymilvus/milvus_client/milvus_client.py", line 725, in _create_connection
    connections.connect(using, user, password, db_name, token, uri=uri, **kwargs)
  File "/home/mocheng/anaconda3/envs/py38/lib/python3.8/site-packages/pymilvus/orm/connections.py", line 449, in connect
    connect_milvus(**kwargs, user=user, password=password, token=token, db_name=db_name)
  File "/home/mocheng/anaconda3/envs/py38/lib/python3.8/site-packages/pymilvus/orm/connections.py", line 400, in connect_milvus
    gh._wait_for_channel_ready(timeout=timeout)
  File "/home/mocheng/anaconda3/envs/py38/lib/python3.8/site-packages/pymilvus/client/grpc_handler.py", line 150, in _wait_for_channel_ready
    raise MilvusException(
pymilvus.exceptions.MilvusException: <MilvusException: (code=2, message=Fail connecting to server on localhost:19530, illegal connection params or server unavailable)>
Command exited with non-zero status 1
	Command being timed: "python -u utils/pymilvus_hnsw.py deep10m 10000000 /mnt/data/mocheng/dataset/deep10m/base.10M.fvecs /mnt/data/mocheng/dataset/deep10m/query.public.10K.fvecs /mnt/data/mocheng/dataset/deep10m/label/sel_1_100000_random/attr_sel_1_100000_random.json /mnt/data/mocheng/dataset/deep10m/label/sel_1_100000_random/qrangesel_8000_1_100000_random.json /mnt/data/mocheng/dataset/deep10m/label/sel_1_100000_random/sif_gt_sel_8000_1_100000_random_10.json 10 40 1000 1000 sel_1_100000_random collection_hnsw_deep10m_sel_1_100000_random_efc1000 query 96"
	User time (seconds): 13.46
	System time (seconds): 0.09
	Percent of CPU this job got: 130%
	Elapsed (wall clock) time (h:mm:ss or m:ss): 0:10.39
	Average shared text size (kbytes): 0
	Average unshared data size (kbytes): 0
	Average stack size (kbytes): 0
	Average total size (kbytes): 0
	Maximum resident set size (kbytes): 83968
	Average resident set size (kbytes): 0
	Major (requiring I/O) page faults: 0
	Minor (reclaiming a frame) page faults: 18350
	Voluntary context switches: 1913
	Involuntary context switches: 121
	Swaps: 0
	File system inputs: 0
	File system outputs: 16
	Socket messages sent: 0
	Socket messages received: 0
	Signals delivered: 0
	Page size (bytes): 4096
	Exit status: 1
Start time: 13:12
dataset: deep10m
N: 10000000
dataset file: /mnt/data/mocheng/dataset/deep10m/base.10M.fvecs
query file: /mnt/data/mocheng/dataset/deep10m/query.public.10K.fvecs
attr file: /mnt/data/mocheng/dataset/deep10m/label/sel_1_100000_random/attr_sel_1_100000_random.json
query range file: /mnt/data/mocheng/dataset/deep10m/label/sel_1_100000_random/qrangesel_9000_1_100000_random.json
ground truth file: /mnt/data/mocheng/dataset/deep10m/label/sel_1_100000_random/sif_gt_sel_9000_1_100000_random_10.json
K: 10
M: 40
ef_construction: 1000
ef_search: 1000
distribution: sel_1_100000_random
collection name: collection_hnsw_deep10m_sel_1_100000_random_efc1000
mode: query
d: 96
Failed to create new connection using: 666490502ea44afcbf0d85ed293ee4e6
Traceback (most recent call last):
  File "utils/pymilvus_hnsw.py", line 75, in <module>
    client = MilvusClient(
  File "/home/mocheng/anaconda3/envs/py38/lib/python3.8/site-packages/pymilvus/milvus_client/milvus_client.py", line 60, in __init__
    self._using = self._create_connection(
  File "/home/mocheng/anaconda3/envs/py38/lib/python3.8/site-packages/pymilvus/milvus_client/milvus_client.py", line 728, in _create_connection
    raise ex from ex
  File "/home/mocheng/anaconda3/envs/py38/lib/python3.8/site-packages/pymilvus/milvus_client/milvus_client.py", line 725, in _create_connection
    connections.connect(using, user, password, db_name, token, uri=uri, **kwargs)
  File "/home/mocheng/anaconda3/envs/py38/lib/python3.8/site-packages/pymilvus/orm/connections.py", line 449, in connect
    connect_milvus(**kwargs, user=user, password=password, token=token, db_name=db_name)
  File "/home/mocheng/anaconda3/envs/py38/lib/python3.8/site-packages/pymilvus/orm/connections.py", line 400, in connect_milvus
    gh._wait_for_channel_ready(timeout=timeout)
  File "/home/mocheng/anaconda3/envs/py38/lib/python3.8/site-packages/pymilvus/client/grpc_handler.py", line 150, in _wait_for_channel_ready
    raise MilvusException(
pymilvus.exceptions.MilvusException: <MilvusException: (code=2, message=Fail connecting to server on localhost:19530, illegal connection params or server unavailable)>
Command exited with non-zero status 1
	Command being timed: "python -u utils/pymilvus_hnsw.py deep10m 10000000 /mnt/data/mocheng/dataset/deep10m/base.10M.fvecs /mnt/data/mocheng/dataset/deep10m/query.public.10K.fvecs /mnt/data/mocheng/dataset/deep10m/label/sel_1_100000_random/attr_sel_1_100000_random.json /mnt/data/mocheng/dataset/deep10m/label/sel_1_100000_random/qrangesel_9000_1_100000_random.json /mnt/data/mocheng/dataset/deep10m/label/sel_1_100000_random/sif_gt_sel_9000_1_100000_random_10.json 10 40 1000 1000 sel_1_100000_random collection_hnsw_deep10m_sel_1_100000_random_efc1000 query 96"
	User time (seconds): 13.48
	System time (seconds): 0.07
	Percent of CPU this job got: 130%
	Elapsed (wall clock) time (h:mm:ss or m:ss): 0:10.38
	Average shared text size (kbytes): 0
	Average unshared data size (kbytes): 0
	Average stack size (kbytes): 0
	Average total size (kbytes): 0
	Maximum resident set size (kbytes): 83968
	Average resident set size (kbytes): 0
	Major (requiring I/O) page faults: 0
	Minor (reclaiming a frame) page faults: 18372
	Voluntary context switches: 1896
	Involuntary context switches: 103
	Swaps: 0
	File system inputs: 0
	File system outputs: 16
	Socket messages sent: 0
	Socket messages received: 0
	Signals delivered: 0
	Page size (bytes): 4096
	Exit status: 1
Start time: 15:26
dataset: deep10m
N: 10000000
dataset file: /mnt/data/mocheng/dataset/deep10m/base.10M.fvecs
query file: /mnt/data/mocheng/dataset/deep10m/query.public.10K.fvecs
attr file: /mnt/data/mocheng/dataset/deep10m/label/sel_1_100000_random/attr_sel_1_100000_random.json
query range file: /mnt/data/mocheng/dataset/deep10m/label/sel_1_100000_random/qrangesel_10000_1_100000_random.json
ground truth file: /mnt/data/mocheng/dataset/deep10m/label/sel_1_100000_random/sif_gt_sel_10000_1_100000_random_10.json
K: 10
M: 40
ef_construction: 1000
ef_search: 1000
distribution: sel_1_100000_random
collection name: collection_hnsw_deep10m_sel_1_100000_random_efc1000
mode: query
d: 96
Failed to create new connection using: 4af2d7948dd74f579783cacfc0b66c95
Traceback (most recent call last):
  File "utils/pymilvus_hnsw.py", line 75, in <module>
    client = MilvusClient(
  File "/home/mocheng/anaconda3/envs/py38/lib/python3.8/site-packages/pymilvus/milvus_client/milvus_client.py", line 60, in __init__
    self._using = self._create_connection(
  File "/home/mocheng/anaconda3/envs/py38/lib/python3.8/site-packages/pymilvus/milvus_client/milvus_client.py", line 728, in _create_connection
    raise ex from ex
  File "/home/mocheng/anaconda3/envs/py38/lib/python3.8/site-packages/pymilvus/milvus_client/milvus_client.py", line 725, in _create_connection
    connections.connect(using, user, password, db_name, token, uri=uri, **kwargs)
  File "/home/mocheng/anaconda3/envs/py38/lib/python3.8/site-packages/pymilvus/orm/connections.py", line 449, in connect
    connect_milvus(**kwargs, user=user, password=password, token=token, db_name=db_name)
  File "/home/mocheng/anaconda3/envs/py38/lib/python3.8/site-packages/pymilvus/orm/connections.py", line 400, in connect_milvus
    gh._wait_for_channel_ready(timeout=timeout)
  File "/home/mocheng/anaconda3/envs/py38/lib/python3.8/site-packages/pymilvus/client/grpc_handler.py", line 150, in _wait_for_channel_ready
    raise MilvusException(
pymilvus.exceptions.MilvusException: <MilvusException: (code=2, message=Fail connecting to server on localhost:19530, illegal connection params or server unavailable)>
Command exited with non-zero status 1
	Command being timed: "python -u utils/pymilvus_hnsw.py deep10m 10000000 /mnt/data/mocheng/dataset/deep10m/base.10M.fvecs /mnt/data/mocheng/dataset/deep10m/query.public.10K.fvecs /mnt/data/mocheng/dataset/deep10m/label/sel_1_100000_random/attr_sel_1_100000_random.json /mnt/data/mocheng/dataset/deep10m/label/sel_1_100000_random/qrangesel_10000_1_100000_random.json /mnt/data/mocheng/dataset/deep10m/label/sel_1_100000_random/sif_gt_sel_10000_1_100000_random_10.json 10 40 1000 1000 sel_1_100000_random collection_hnsw_deep10m_sel_1_100000_random_efc1000 query 96"
	User time (seconds): 13.42
	System time (seconds): 0.13
	Percent of CPU this job got: 130%
	Elapsed (wall clock) time (h:mm:ss or m:ss): 0:10.39
	Average shared text size (kbytes): 0
	Average unshared data size (kbytes): 0
	Average stack size (kbytes): 0
	Average total size (kbytes): 0
	Maximum resident set size (kbytes): 83968
	Average resident set size (kbytes): 0
	Major (requiring I/O) page faults: 0
	Minor (reclaiming a frame) page faults: 18394
	Voluntary context switches: 1948
	Involuntary context switches: 408
	Swaps: 0
	File system inputs: 0
	File system outputs: 24
	Socket messages sent: 0
	Socket messages received: 0
	Signals delivered: 0
	Page size (bytes): 4096
	Exit status: 1
