Start time: 04:17
dataset: spacev10m
N: 10000000
dataset file: /mnt/data/mocheng/dataset/spacev10m/base10M.fvecs
query file: /mnt/data/mocheng/dataset/spacev10m/query10k.fvecs
attr file: /mnt/data/mocheng/dataset/spacev10m/label/sel_1_500_random/attr_sel_1_500_random.json
query range file: /mnt/data/mocheng/dataset/spacev10m/label/sel_1_500_random/qrangesel_1_1_500_random_6.json
ground truth file: /mnt/data/mocheng/dataset/spacev10m/label/sel_1_500_random/sif_gt_sel_1_1_500_random_6_100.json
K: 100
M: 40
ef_construction: 1000
ef_search: 1000
distribution: sel_1_500_random
collection name: collection_hnsw_spacev10m_sel_1_500_random_efc1000
mode: query
d: 100
2025-07-12 19:18:04,206 [ERROR][_create_connection]: Failed to create new connection using: 8948e303ce4d4c4eb8268d3b6b48bf4c (milvus_client.py:923)
Traceback (most recent call last):
  File "utils/pymilvus_hnsw.py", line 75, in <module>
    client = MilvusClient(
  File "/home/mocheng/anaconda3/envs/py38/lib/python3.8/site-packages/pymilvus/milvus_client/milvus_client.py", line 67, in __init__
    self._using = self._create_connection(
  File "/home/mocheng/anaconda3/envs/py38/lib/python3.8/site-packages/pymilvus/milvus_client/milvus_client.py", line 924, in _create_connection
    raise ex from ex
  File "/home/mocheng/anaconda3/envs/py38/lib/python3.8/site-packages/pymilvus/milvus_client/milvus_client.py", line 921, in _create_connection
    connections.connect(using, user, password, db_name, token, uri=uri, **kwargs)
  File "/home/mocheng/anaconda3/envs/py38/lib/python3.8/site-packages/pymilvus/orm/connections.py", line 461, in connect
    connect_milvus(**kwargs, user=user, password=password, token=token, db_name=db_name)
  File "/home/mocheng/anaconda3/envs/py38/lib/python3.8/site-packages/pymilvus/orm/connections.py", line 411, in connect_milvus
    gh._wait_for_channel_ready(timeout=timeout)
  File "/home/mocheng/anaconda3/envs/py38/lib/python3.8/site-packages/pymilvus/client/grpc_handler.py", line 155, in _wait_for_channel_ready
    raise MilvusException(
pymilvus.exceptions.MilvusException: <MilvusException: (code=2, message=Fail connecting to server on localhost:19530, illegal connection params or server unavailable)>
Command exited with non-zero status 1
	Command being timed: "python -u utils/pymilvus_hnsw.py spacev10m 10000000 /mnt/data/mocheng/dataset/spacev10m/base10M.fvecs /mnt/data/mocheng/dataset/spacev10m/query10k.fvecs /mnt/data/mocheng/dataset/spacev10m/label/sel_1_500_random/attr_sel_1_500_random.json /mnt/data/mocheng/dataset/spacev10m/label/sel_1_500_random/qrangesel_1_1_500_random_6.json /mnt/data/mocheng/dataset/spacev10m/label/sel_1_500_random/sif_gt_sel_1_1_500_random_6_100.json 100 40 1000 1000 sel_1_500_random collection_hnsw_spacev10m_sel_1_500_random_efc1000 query 100"
	User time (seconds): 2.24
	System time (seconds): 0.08
	Percent of CPU this job got: 21%
	Elapsed (wall clock) time (h:mm:ss or m:ss): 0:10.71
	Average shared text size (kbytes): 0
	Average unshared data size (kbytes): 0
	Average stack size (kbytes): 0
	Average total size (kbytes): 0
	Maximum resident set size (kbytes): 78848
	Average resident set size (kbytes): 0
	Major (requiring I/O) page faults: 29
	Minor (reclaiming a frame) page faults: 22161
	Voluntary context switches: 2125
	Involuntary context switches: 508
	Swaps: 0
	File system inputs: 1560
	File system outputs: 8
	Socket messages sent: 0
	Socket messages received: 0
	Signals delivered: 0
	Page size (bytes): 4096
	Exit status: 1
Start time: 04:46
dataset: spacev10m
N: 10000000
dataset file: /mnt/data/mocheng/dataset/spacev10m/base10M.fvecs
query file: /mnt/data/mocheng/dataset/spacev10m/query10k.fvecs
attr file: /mnt/data/mocheng/dataset/spacev10m/label/sel_1_500_random/attr_sel_1_500_random.json
query range file: /mnt/data/mocheng/dataset/spacev10m/label/sel_1_500_random/qrangesel_1_1_500_random_10.json
ground truth file: /mnt/data/mocheng/dataset/spacev10m/label/sel_1_500_random/sif_gt_sel_1_1_500_random_10_100.json
K: 100
M: 40
ef_construction: 1000
ef_search: 1000
distribution: sel_1_500_random
collection name: collection_hnsw_spacev10m_sel_1_500_random_efc1000
mode: query
d: 100
2025-07-12 19:46:28,879 [ERROR][_create_connection]: Failed to create new connection using: 1c630050ca274822aff4773dcdcdb3f0 (milvus_client.py:923)
Traceback (most recent call last):
  File "utils/pymilvus_hnsw.py", line 75, in <module>
    client = MilvusClient(
  File "/home/mocheng/anaconda3/envs/py38/lib/python3.8/site-packages/pymilvus/milvus_client/milvus_client.py", line 67, in __init__
    self._using = self._create_connection(
  File "/home/mocheng/anaconda3/envs/py38/lib/python3.8/site-packages/pymilvus/milvus_client/milvus_client.py", line 924, in _create_connection
    raise ex from ex
  File "/home/mocheng/anaconda3/envs/py38/lib/python3.8/site-packages/pymilvus/milvus_client/milvus_client.py", line 921, in _create_connection
    connections.connect(using, user, password, db_name, token, uri=uri, **kwargs)
  File "/home/mocheng/anaconda3/envs/py38/lib/python3.8/site-packages/pymilvus/orm/connections.py", line 461, in connect
    connect_milvus(**kwargs, user=user, password=password, token=token, db_name=db_name)
  File "/home/mocheng/anaconda3/envs/py38/lib/python3.8/site-packages/pymilvus/orm/connections.py", line 411, in connect_milvus
    gh._wait_for_channel_ready(timeout=timeout)
  File "/home/mocheng/anaconda3/envs/py38/lib/python3.8/site-packages/pymilvus/client/grpc_handler.py", line 155, in _wait_for_channel_ready
    raise MilvusException(
pymilvus.exceptions.MilvusException: <MilvusException: (code=2, message=Fail connecting to server on localhost:19530, illegal connection params or server unavailable)>
Command exited with non-zero status 1
	Command being timed: "python -u utils/pymilvus_hnsw.py spacev10m 10000000 /mnt/data/mocheng/dataset/spacev10m/base10M.fvecs /mnt/data/mocheng/dataset/spacev10m/query10k.fvecs /mnt/data/mocheng/dataset/spacev10m/label/sel_1_500_random/attr_sel_1_500_random.json /mnt/data/mocheng/dataset/spacev10m/label/sel_1_500_random/qrangesel_1_1_500_random_10.json /mnt/data/mocheng/dataset/spacev10m/label/sel_1_500_random/sif_gt_sel_1_1_500_random_10_100.json 100 40 1000 1000 sel_1_500_random collection_hnsw_spacev10m_sel_1_500_random_efc1000 query 100"
	User time (seconds): 2.05
	System time (seconds): 0.10
	Percent of CPU this job got: 20%
	Elapsed (wall clock) time (h:mm:ss or m:ss): 0:10.71
	Average shared text size (kbytes): 0
	Average unshared data size (kbytes): 0
	Average stack size (kbytes): 0
	Average total size (kbytes): 0
	Maximum resident set size (kbytes): 77824
	Average resident set size (kbytes): 0
	Major (requiring I/O) page faults: 30
	Minor (reclaiming a frame) page faults: 22166
	Voluntary context switches: 2186
	Involuntary context switches: 354
	Swaps: 0
	File system inputs: 1920
	File system outputs: 16
	Socket messages sent: 0
	Socket messages received: 0
	Signals delivered: 0
	Page size (bytes): 4096
	Exit status: 1
Start time: 05:12
dataset: spacev10m
N: 10000000
dataset file: /mnt/data/mocheng/dataset/spacev10m/base10M.fvecs
query file: /mnt/data/mocheng/dataset/spacev10m/query10k.fvecs
attr file: /mnt/data/mocheng/dataset/spacev10m/label/sel_1_500_random/attr_sel_1_500_random.json
query range file: /mnt/data/mocheng/dataset/spacev10m/label/sel_1_500_random/qrangesel_1_1_500_random_19.json
ground truth file: /mnt/data/mocheng/dataset/spacev10m/label/sel_1_500_random/sif_gt_sel_1_1_500_random_19_100.json
K: 100
M: 40
ef_construction: 1000
ef_search: 1000
distribution: sel_1_500_random
collection name: collection_hnsw_spacev10m_sel_1_500_random_efc1000
mode: query
d: 100
2025-07-12 20:12:31,520 [ERROR][_create_connection]: Failed to create new connection using: 0ea57d393eff402c8a1cbf49b73eadd1 (milvus_client.py:923)
Traceback (most recent call last):
  File "utils/pymilvus_hnsw.py", line 75, in <module>
    client = MilvusClient(
  File "/home/mocheng/anaconda3/envs/py38/lib/python3.8/site-packages/pymilvus/milvus_client/milvus_client.py", line 67, in __init__
    self._using = self._create_connection(
  File "/home/mocheng/anaconda3/envs/py38/lib/python3.8/site-packages/pymilvus/milvus_client/milvus_client.py", line 924, in _create_connection
    raise ex from ex
  File "/home/mocheng/anaconda3/envs/py38/lib/python3.8/site-packages/pymilvus/milvus_client/milvus_client.py", line 921, in _create_connection
    connections.connect(using, user, password, db_name, token, uri=uri, **kwargs)
  File "/home/mocheng/anaconda3/envs/py38/lib/python3.8/site-packages/pymilvus/orm/connections.py", line 461, in connect
    connect_milvus(**kwargs, user=user, password=password, token=token, db_name=db_name)
  File "/home/mocheng/anaconda3/envs/py38/lib/python3.8/site-packages/pymilvus/orm/connections.py", line 411, in connect_milvus
    gh._wait_for_channel_ready(timeout=timeout)
  File "/home/mocheng/anaconda3/envs/py38/lib/python3.8/site-packages/pymilvus/client/grpc_handler.py", line 155, in _wait_for_channel_ready
    raise MilvusException(
pymilvus.exceptions.MilvusException: <MilvusException: (code=2, message=Fail connecting to server on localhost:19530, illegal connection params or server unavailable)>
Command exited with non-zero status 1
	Command being timed: "python -u utils/pymilvus_hnsw.py spacev10m 10000000 /mnt/data/mocheng/dataset/spacev10m/base10M.fvecs /mnt/data/mocheng/dataset/spacev10m/query10k.fvecs /mnt/data/mocheng/dataset/spacev10m/label/sel_1_500_random/attr_sel_1_500_random.json /mnt/data/mocheng/dataset/spacev10m/label/sel_1_500_random/qrangesel_1_1_500_random_19.json /mnt/data/mocheng/dataset/spacev10m/label/sel_1_500_random/sif_gt_sel_1_1_500_random_19_100.json 100 40 1000 1000 sel_1_500_random collection_hnsw_spacev10m_sel_1_500_random_efc1000 query 100"
	User time (seconds): 2.44
	System time (seconds): 37.37
	Percent of CPU this job got: 168%
	Elapsed (wall clock) time (h:mm:ss or m:ss): 0:23.56
	Average shared text size (kbytes): 0
	Average unshared data size (kbytes): 0
	Average stack size (kbytes): 0
	Average total size (kbytes): 0
	Maximum resident set size (kbytes): 75776
	Average resident set size (kbytes): 0
	Major (requiring I/O) page faults: 950
	Minor (reclaiming a frame) page faults: 45423
	Voluntary context switches: 5011
	Involuntary context switches: 3237
	Swaps: 0
	File system inputs: 259336
	File system outputs: 16
	Socket messages sent: 0
	Socket messages received: 0
	Signals delivered: 0
	Page size (bytes): 4096
	Exit status: 1
Start time: 05:39
dataset: spacev10m
N: 10000000
dataset file: /mnt/data/mocheng/dataset/spacev10m/base10M.fvecs
query file: /mnt/data/mocheng/dataset/spacev10m/query10k.fvecs
attr file: /mnt/data/mocheng/dataset/spacev10m/label/sel_1_500_random/attr_sel_1_500_random.json
query range file: /mnt/data/mocheng/dataset/spacev10m/label/sel_1_500_random/qrangesel_1_1_500_random_20.json
ground truth file: /mnt/data/mocheng/dataset/spacev10m/label/sel_1_500_random/sif_gt_sel_1_1_500_random_20_100.json
K: 100
M: 40
ef_construction: 1000
ef_search: 1000
distribution: sel_1_500_random
collection name: collection_hnsw_spacev10m_sel_1_500_random_efc1000
mode: query
d: 100
2025-07-12 20:39:43,949 [ERROR][_create_connection]: Failed to create new connection using: 4a3b31a39f9848b2b33355e51537880f (milvus_client.py:923)
Traceback (most recent call last):
  File "utils/pymilvus_hnsw.py", line 75, in <module>
    client = MilvusClient(
  File "/home/mocheng/anaconda3/envs/py38/lib/python3.8/site-packages/pymilvus/milvus_client/milvus_client.py", line 67, in __init__
    self._using = self._create_connection(
  File "/home/mocheng/anaconda3/envs/py38/lib/python3.8/site-packages/pymilvus/milvus_client/milvus_client.py", line 924, in _create_connection
    raise ex from ex
  File "/home/mocheng/anaconda3/envs/py38/lib/python3.8/site-packages/pymilvus/milvus_client/milvus_client.py", line 921, in _create_connection
    connections.connect(using, user, password, db_name, token, uri=uri, **kwargs)
  File "/home/mocheng/anaconda3/envs/py38/lib/python3.8/site-packages/pymilvus/orm/connections.py", line 461, in connect
    connect_milvus(**kwargs, user=user, password=password, token=token, db_name=db_name)
  File "/home/mocheng/anaconda3/envs/py38/lib/python3.8/site-packages/pymilvus/orm/connections.py", line 411, in connect_milvus
    gh._wait_for_channel_ready(timeout=timeout)
  File "/home/mocheng/anaconda3/envs/py38/lib/python3.8/site-packages/pymilvus/client/grpc_handler.py", line 155, in _wait_for_channel_ready
    raise MilvusException(
pymilvus.exceptions.MilvusException: <MilvusException: (code=2, message=Fail connecting to server on localhost:19530, illegal connection params or server unavailable)>
Command exited with non-zero status 1
	Command being timed: "python -u utils/pymilvus_hnsw.py spacev10m 10000000 /mnt/data/mocheng/dataset/spacev10m/base10M.fvecs /mnt/data/mocheng/dataset/spacev10m/query10k.fvecs /mnt/data/mocheng/dataset/spacev10m/label/sel_1_500_random/attr_sel_1_500_random.json /mnt/data/mocheng/dataset/spacev10m/label/sel_1_500_random/qrangesel_1_1_500_random_20.json /mnt/data/mocheng/dataset/spacev10m/label/sel_1_500_random/sif_gt_sel_1_1_500_random_20_100.json 100 40 1000 1000 sel_1_500_random collection_hnsw_spacev10m_sel_1_500_random_efc1000 query 100"
	User time (seconds): 1.83
	System time (seconds): 0.11
	Percent of CPU this job got: 18%
	Elapsed (wall clock) time (h:mm:ss or m:ss): 0:10.74
	Average shared text size (kbytes): 0
	Average unshared data size (kbytes): 0
	Average stack size (kbytes): 0
	Average total size (kbytes): 0
	Maximum resident set size (kbytes): 75776
	Average resident set size (kbytes): 0
	Major (requiring I/O) page faults: 29
	Minor (reclaiming a frame) page faults: 22146
	Voluntary context switches: 2104
	Involuntary context switches: 492
	Swaps: 0
	File system inputs: 1272
	File system outputs: 16
	Socket messages sent: 0
	Socket messages received: 0
	Signals delivered: 0
	Page size (bytes): 4096
	Exit status: 1
