Start time: 06:01
dataset: redcaps1m
N: 1000000
dataset file: /mnt/data/mocheng/dataset/redcaps1m/image_embeddings.fvecs
query file: /mnt/data/mocheng/dataset/redcaps1m/query.fvecs
attr file: /mnt/data/mocheng/dataset/redcaps1m/label/sel_1_500_random_6/attr_sel_1_500_random_6.json
query range file: /mnt/data/mocheng/dataset/redcaps1m/label/sel_1_500_random_6/qrangesel_1_1_500_random_6.json
ground truth file: /mnt/data/mocheng/dataset/redcaps1m/label/sel_1_500_random_6/sif_gt_sel_1_1_500_random_6_100.json
K: 100
nprobe: 80
collection name: collection_redcaps1m_sel_1_500_random_6_256
2025-07-12 21:01:47,230 [ERROR][_create_connection]: Failed to create new connection using: a1c5b0e643df4151954ef701fa665b04 (milvus_client.py:923)
Traceback (most recent call last):
  File "utils/pymilvus_ivfpq.py", line 67, in <module>
    client = MilvusClient(
  File "/home/mocheng/anaconda3/envs/py38/lib/python3.8/site-packages/pymilvus/milvus_client/milvus_client.py", line 67, in __init__
    self._using = self._create_connection(
  File "/home/mocheng/anaconda3/envs/py38/lib/python3.8/site-packages/pymilvus/milvus_client/milvus_client.py", line 924, in _create_connection
    raise ex from ex
  File "/home/mocheng/anaconda3/envs/py38/lib/python3.8/site-packages/pymilvus/milvus_client/milvus_client.py", line 921, in _create_connection
    connections.connect(using, user, password, db_name, token, uri=uri, **kwargs)
  File "/home/mocheng/anaconda3/envs/py38/lib/python3.8/site-packages/pymilvus/orm/connections.py", line 461, in connect
    connect_milvus(**kwargs, user=user, password=password, token=token, db_name=db_name)
  File "/home/mocheng/anaconda3/envs/py38/lib/python3.8/site-packages/pymilvus/orm/connections.py", line 411, in connect_milvus
    gh._wait_for_channel_ready(timeout=timeout)
  File "/home/mocheng/anaconda3/envs/py38/lib/python3.8/site-packages/pymilvus/client/grpc_handler.py", line 155, in _wait_for_channel_ready
    raise MilvusException(
pymilvus.exceptions.MilvusException: <MilvusException: (code=2, message=Fail connecting to server on localhost:19530, illegal connection params or server unavailable)>
Command exited with non-zero status 1
	Command being timed: "python -u utils/pymilvus_ivfpq.py redcaps1m 1000000 /mnt/data/mocheng/dataset/redcaps1m/image_embeddings.fvecs /mnt/data/mocheng/dataset/redcaps1m/query.fvecs /mnt/data/mocheng/dataset/redcaps1m/label/sel_1_500_random_6/attr_sel_1_500_random_6.json /mnt/data/mocheng/dataset/redcaps1m/label/sel_1_500_random_6/qrangesel_1_1_500_random_6.json /mnt/data/mocheng/dataset/redcaps1m/label/sel_1_500_random_6/sif_gt_sel_1_1_500_random_6_100.json 100 80 collection_redcaps1m_sel_1_500_random_6_256 query 256 512"
	User time (seconds): 2.30
	System time (seconds): 0.11
	Percent of CPU this job got: 22%
	Elapsed (wall clock) time (h:mm:ss or m:ss): 0:10.61
	Average shared text size (kbytes): 0
	Average unshared data size (kbytes): 0
	Average stack size (kbytes): 0
	Average total size (kbytes): 0
	Maximum resident set size (kbytes): 76800
	Average resident set size (kbytes): 0
	Major (requiring I/O) page faults: 0
	Minor (reclaiming a frame) page faults: 22079
	Voluntary context switches: 1913
	Involuntary context switches: 530
	Swaps: 0
	File system inputs: 0
	File system outputs: 8
	Socket messages sent: 0
	Socket messages received: 0
	Signals delivered: 0
	Page size (bytes): 4096
	Exit status: 1
Start time: 06:10
dataset: redcaps1m
N: 1000000
dataset file: /mnt/data/mocheng/dataset/redcaps1m/image_embeddings.fvecs
query file: /mnt/data/mocheng/dataset/redcaps1m/query.fvecs
attr file: /mnt/data/mocheng/dataset/redcaps1m/label/sel_1_500_random_10/attr_sel_1_500_random_10.json
query range file: /mnt/data/mocheng/dataset/redcaps1m/label/sel_1_500_random_10/qrangesel_1_1_500_random_10.json
ground truth file: /mnt/data/mocheng/dataset/redcaps1m/label/sel_1_500_random_10/sif_gt_sel_1_1_500_random_10_100.json
K: 100
nprobe: 80
collection name: collection_redcaps1m_sel_1_500_random_10_256
2025-07-12 21:10:36,781 [ERROR][_create_connection]: Failed to create new connection using: 6874ac2c70fa445b9d0672277f56377e (milvus_client.py:923)
Traceback (most recent call last):
  File "utils/pymilvus_ivfpq.py", line 67, in <module>
    client = MilvusClient(
  File "/home/mocheng/anaconda3/envs/py38/lib/python3.8/site-packages/pymilvus/milvus_client/milvus_client.py", line 67, in __init__
    self._using = self._create_connection(
  File "/home/mocheng/anaconda3/envs/py38/lib/python3.8/site-packages/pymilvus/milvus_client/milvus_client.py", line 924, in _create_connection
    raise ex from ex
  File "/home/mocheng/anaconda3/envs/py38/lib/python3.8/site-packages/pymilvus/milvus_client/milvus_client.py", line 921, in _create_connection
    connections.connect(using, user, password, db_name, token, uri=uri, **kwargs)
  File "/home/mocheng/anaconda3/envs/py38/lib/python3.8/site-packages/pymilvus/orm/connections.py", line 461, in connect
    connect_milvus(**kwargs, user=user, password=password, token=token, db_name=db_name)
  File "/home/mocheng/anaconda3/envs/py38/lib/python3.8/site-packages/pymilvus/orm/connections.py", line 411, in connect_milvus
    gh._wait_for_channel_ready(timeout=timeout)
  File "/home/mocheng/anaconda3/envs/py38/lib/python3.8/site-packages/pymilvus/client/grpc_handler.py", line 155, in _wait_for_channel_ready
    raise MilvusException(
pymilvus.exceptions.MilvusException: <MilvusException: (code=2, message=Fail connecting to server on localhost:19530, illegal connection params or server unavailable)>
Command exited with non-zero status 1
	Command being timed: "python -u utils/pymilvus_ivfpq.py redcaps1m 1000000 /mnt/data/mocheng/dataset/redcaps1m/image_embeddings.fvecs /mnt/data/mocheng/dataset/redcaps1m/query.fvecs /mnt/data/mocheng/dataset/redcaps1m/label/sel_1_500_random_10/attr_sel_1_500_random_10.json /mnt/data/mocheng/dataset/redcaps1m/label/sel_1_500_random_10/qrangesel_1_1_500_random_10.json /mnt/data/mocheng/dataset/redcaps1m/label/sel_1_500_random_10/sif_gt_sel_1_1_500_random_10_100.json 100 80 collection_redcaps1m_sel_1_500_random_10_256 query 256 512"
	User time (seconds): 3.07
	System time (seconds): 0.12
	Percent of CPU this job got: 30%
	Elapsed (wall clock) time (h:mm:ss or m:ss): 0:10.63
	Average shared text size (kbytes): 0
	Average unshared data size (kbytes): 0
	Average stack size (kbytes): 0
	Average total size (kbytes): 0
	Maximum resident set size (kbytes): 77824
	Average resident set size (kbytes): 0
	Major (requiring I/O) page faults: 0
	Minor (reclaiming a frame) page faults: 22090
	Voluntary context switches: 1888
	Involuntary context switches: 469
	Swaps: 0
	File system inputs: 0
	File system outputs: 16
	Socket messages sent: 0
	Socket messages received: 0
	Signals delivered: 0
	Page size (bytes): 4096
	Exit status: 1
Start time: 06:17
dataset: redcaps1m
N: 1000000
dataset file: /mnt/data/mocheng/dataset/redcaps1m/image_embeddings.fvecs
query file: /mnt/data/mocheng/dataset/redcaps1m/query.fvecs
attr file: /mnt/data/mocheng/dataset/redcaps1m/label/sel_1_500_random_19/attr_sel_1_500_random_19.json
query range file: /mnt/data/mocheng/dataset/redcaps1m/label/sel_1_500_random_19/qrangesel_1_1_500_random_19.json
ground truth file: /mnt/data/mocheng/dataset/redcaps1m/label/sel_1_500_random_19/sif_gt_sel_1_1_500_random_19_100.json
K: 100
nprobe: 80
collection name: collection_redcaps1m_sel_1_500_random_19_256
2025-07-12 21:18:00,714 [ERROR][_create_connection]: Failed to create new connection using: 82110d98e3134dd6bd7831cd268ff937 (milvus_client.py:923)
Traceback (most recent call last):
  File "utils/pymilvus_ivfpq.py", line 67, in <module>
    client = MilvusClient(
  File "/home/mocheng/anaconda3/envs/py38/lib/python3.8/site-packages/pymilvus/milvus_client/milvus_client.py", line 67, in __init__
    self._using = self._create_connection(
  File "/home/mocheng/anaconda3/envs/py38/lib/python3.8/site-packages/pymilvus/milvus_client/milvus_client.py", line 924, in _create_connection
    raise ex from ex
  File "/home/mocheng/anaconda3/envs/py38/lib/python3.8/site-packages/pymilvus/milvus_client/milvus_client.py", line 921, in _create_connection
    connections.connect(using, user, password, db_name, token, uri=uri, **kwargs)
  File "/home/mocheng/anaconda3/envs/py38/lib/python3.8/site-packages/pymilvus/orm/connections.py", line 461, in connect
    connect_milvus(**kwargs, user=user, password=password, token=token, db_name=db_name)
  File "/home/mocheng/anaconda3/envs/py38/lib/python3.8/site-packages/pymilvus/orm/connections.py", line 411, in connect_milvus
    gh._wait_for_channel_ready(timeout=timeout)
  File "/home/mocheng/anaconda3/envs/py38/lib/python3.8/site-packages/pymilvus/client/grpc_handler.py", line 155, in _wait_for_channel_ready
    raise MilvusException(
pymilvus.exceptions.MilvusException: <MilvusException: (code=2, message=Fail connecting to server on localhost:19530, illegal connection params or server unavailable)>
Command exited with non-zero status 1
	Command being timed: "python -u utils/pymilvus_ivfpq.py redcaps1m 1000000 /mnt/data/mocheng/dataset/redcaps1m/image_embeddings.fvecs /mnt/data/mocheng/dataset/redcaps1m/query.fvecs /mnt/data/mocheng/dataset/redcaps1m/label/sel_1_500_random_19/attr_sel_1_500_random_19.json /mnt/data/mocheng/dataset/redcaps1m/label/sel_1_500_random_19/qrangesel_1_1_500_random_19.json /mnt/data/mocheng/dataset/redcaps1m/label/sel_1_500_random_19/sif_gt_sel_1_1_500_random_19_100.json 100 80 collection_redcaps1m_sel_1_500_random_19_256 query 256 512"
	User time (seconds): 2.08
	System time (seconds): 0.10
	Percent of CPU this job got: 20%
	Elapsed (wall clock) time (h:mm:ss or m:ss): 0:10.59
	Average shared text size (kbytes): 0
	Average unshared data size (kbytes): 0
	Average stack size (kbytes): 0
	Average total size (kbytes): 0
	Maximum resident set size (kbytes): 77820
	Average resident set size (kbytes): 0
	Major (requiring I/O) page faults: 0
	Minor (reclaiming a frame) page faults: 22102
	Voluntary context switches: 1868
	Involuntary context switches: 605
	Swaps: 0
	File system inputs: 0
	File system outputs: 16
	Socket messages sent: 0
	Socket messages received: 0
	Signals delivered: 0
	Page size (bytes): 4096
	Exit status: 1
Start time: 06:23
dataset: redcaps1m
N: 1000000
dataset file: /mnt/data/mocheng/dataset/redcaps1m/image_embeddings.fvecs
query file: /mnt/data/mocheng/dataset/redcaps1m/query.fvecs
attr file: /mnt/data/mocheng/dataset/redcaps1m/label/sel_1_500_random_20/attr_sel_1_500_random_20.json
query range file: /mnt/data/mocheng/dataset/redcaps1m/label/sel_1_500_random_20/qrangesel_1_1_500_random_20.json
ground truth file: /mnt/data/mocheng/dataset/redcaps1m/label/sel_1_500_random_20/sif_gt_sel_1_1_500_random_20_100.json
K: 100
nprobe: 80
collection name: collection_redcaps1m_sel_1_500_random_20_256
2025-07-12 21:23:13,192 [ERROR][_create_connection]: Failed to create new connection using: 942d4910143c4c21bd8db1edc82375e9 (milvus_client.py:923)
Traceback (most recent call last):
  File "utils/pymilvus_ivfpq.py", line 67, in <module>
    client = MilvusClient(
  File "/home/mocheng/anaconda3/envs/py38/lib/python3.8/site-packages/pymilvus/milvus_client/milvus_client.py", line 67, in __init__
    self._using = self._create_connection(
  File "/home/mocheng/anaconda3/envs/py38/lib/python3.8/site-packages/pymilvus/milvus_client/milvus_client.py", line 924, in _create_connection
    raise ex from ex
  File "/home/mocheng/anaconda3/envs/py38/lib/python3.8/site-packages/pymilvus/milvus_client/milvus_client.py", line 921, in _create_connection
    connections.connect(using, user, password, db_name, token, uri=uri, **kwargs)
  File "/home/mocheng/anaconda3/envs/py38/lib/python3.8/site-packages/pymilvus/orm/connections.py", line 461, in connect
    connect_milvus(**kwargs, user=user, password=password, token=token, db_name=db_name)
  File "/home/mocheng/anaconda3/envs/py38/lib/python3.8/site-packages/pymilvus/orm/connections.py", line 411, in connect_milvus
    gh._wait_for_channel_ready(timeout=timeout)
  File "/home/mocheng/anaconda3/envs/py38/lib/python3.8/site-packages/pymilvus/client/grpc_handler.py", line 155, in _wait_for_channel_ready
    raise MilvusException(
pymilvus.exceptions.MilvusException: <MilvusException: (code=2, message=Fail connecting to server on localhost:19530, illegal connection params or server unavailable)>
Command exited with non-zero status 1
	Command being timed: "python -u utils/pymilvus_ivfpq.py redcaps1m 1000000 /mnt/data/mocheng/dataset/redcaps1m/image_embeddings.fvecs /mnt/data/mocheng/dataset/redcaps1m/query.fvecs /mnt/data/mocheng/dataset/redcaps1m/label/sel_1_500_random_20/attr_sel_1_500_random_20.json /mnt/data/mocheng/dataset/redcaps1m/label/sel_1_500_random_20/qrangesel_1_1_500_random_20.json /mnt/data/mocheng/dataset/redcaps1m/label/sel_1_500_random_20/sif_gt_sel_1_1_500_random_20_100.json 100 80 collection_redcaps1m_sel_1_500_random_20_256 query 256 512"
	User time (seconds): 1.81
	System time (seconds): 0.07
	Percent of CPU this job got: 17%
	Elapsed (wall clock) time (h:mm:ss or m:ss): 0:10.67
	Average shared text size (kbytes): 0
	Average unshared data size (kbytes): 0
	Average stack size (kbytes): 0
	Average total size (kbytes): 0
	Maximum resident set size (kbytes): 78848
	Average resident set size (kbytes): 0
	Major (requiring I/O) page faults: 0
	Minor (reclaiming a frame) page faults: 22088
	Voluntary context switches: 1821
	Involuntary context switches: 412
	Swaps: 0
	File system inputs: 0
	File system outputs: 16
	Socket messages sent: 0
	Socket messages received: 0
	Signals delivered: 0
	Page size (bytes): 4096
	Exit status: 1
